#### syntax error must be corrected.

---


#### std::logic_error : preventable : cannot be thrown directly.

        Defines a type of object to be thrown as exception. 
        It reports errors that are a consequence of faulty logic within the program such as violating 
        logical preconditions or class invariants and may be preventable.

        No standard library components throw this exception directly, 
        but the exception types 
        std::invalid_argument, 
        std::domain_error, 
        std::length_error, 
        std::out_of_range, 
        std::future_error, and 
        std::experimental::bad_optional_access 
        are derived from std::logic_error. 


       ex: std::out_of_range : error : preventable, check the size first
       
                
       
       // out_of_range example
        #include <iostream>       // std::cerr
        #include <stdexcept>      // std::out_of_range
        #include <vector>         // std::vector

        int main (void) {
          std::vector<int> myvector(10);
          try {
            // check the size first
            // std::cout << myvector.size() << std::endl;              
            myvector.at(20)=100;      // vector::at throws an out-of-range
          }
          catch (const std::out_of_range& oor) {
            std::cerr << "Out of Range error: " << oor.what() << '\n';
          }
          return 0;
        }
        
        output : 
        Out of Range error: vector::_M_range_check: __n (which is 20) >= this->size() (which is 10)


---

#### business logic error : handled by custom/userdefine excpetion.
